2025-03-17 12:55:41,861 django.utils.autoreload INFO     Watching for file changes with StatReloader
2025-03-17 12:56:11,765 django.utils.autoreload INFO     Watching for file changes with StatReloader
2025-03-17 12:57:02,081 django.utils.autoreload INFO     /app/cpq/settings.py changed, reloading.
2025-03-17 14:04:19,627 django.utils.autoreload INFO     Watching for file changes with StatReloader
2025-03-17 14:05:01,960 django.utils.autoreload INFO     /app/cpq/settings.py changed, reloading.
2025-03-17 14:05:02,430 django.utils.autoreload INFO     Watching for file changes with StatReloader
2025-03-17 14:06:04,995 django.utils.autoreload INFO     Watching for file changes with StatReloader
2025-03-17 14:07:06,322 django.utils.autoreload INFO     /app/configurator/admin.py changed, reloading.
2025-03-17 14:07:06,723 django.utils.autoreload INFO     Watching for file changes with StatReloader
2025-03-17 14:07:47,990 django.utils.autoreload INFO     /app/configurator/admin.py changed, reloading.
2025-03-17 14:07:48,227 django.utils.autoreload INFO     Watching for file changes with StatReloader
2025-03-17 14:07:57,385 django.utils.autoreload INFO     /app/configurator/admin.py changed, reloading.
2025-03-17 14:07:57,600 django.utils.autoreload INFO     Watching for file changes with StatReloader
2025-03-17 14:09:46,074 django.utils.autoreload INFO     /app/configurator/admin.py changed, reloading.
2025-03-17 14:09:46,297 django.utils.autoreload INFO     Watching for file changes with StatReloader
2025-03-18 12:32:06,174 django.utils.autoreload INFO     Watching for file changes with StatReloader
2025-03-18 12:44:28,569 django.utils.autoreload INFO     /app/configurator/models.py changed, reloading.
2025-03-18 12:44:28,792 django.utils.autoreload INFO     Watching for file changes with StatReloader
2025-03-18 12:45:06,042 django.utils.autoreload INFO     /app/configurator/admin.py changed, reloading.
2025-03-18 12:45:06,282 django.utils.autoreload INFO     Watching for file changes with StatReloader
2025-03-18 12:45:59,390 django.utils.autoreload INFO     Watching for file changes with StatReloader
2025-03-18 13:22:21,001 django.request WARNING  Not Found: /favicon.ico
2025-03-18 13:22:36,860 django.request ERROR    Internal Server Error: /admin/configurator/item/
Traceback (most recent call last):
  File "/usr/local/lib/python3.12/site-packages/django/db/backends/utils.py", line 105, in _execute
    return self.cursor.execute(sql, params)
           ^^^^^^^^^^^^^^^^^^^^^^^^^^^^^^^^
psycopg2.errors.UndefinedTable: relation "configurator_item" does not exist
LINE 1: SELECT COUNT(*) AS "__count" FROM "configurator_item"
                                          ^


The above exception was the direct cause of the following exception:

Traceback (most recent call last):
  File "/usr/local/lib/python3.12/site-packages/django/core/handlers/exception.py", line 55, in inner
    response = get_response(request)
               ^^^^^^^^^^^^^^^^^^^^^
  File "/usr/local/lib/python3.12/site-packages/django/core/handlers/base.py", line 197, in _get_response
    response = wrapped_callback(request, *callback_args, **callback_kwargs)
               ^^^^^^^^^^^^^^^^^^^^^^^^^^^^^^^^^^^^^^^^^^^^^^^^^^^^^^^^^^^^
  File "/usr/local/lib/python3.12/site-packages/django/contrib/admin/options.py", line 718, in wrapper
    return self.admin_site.admin_view(view)(*args, **kwargs)
           ^^^^^^^^^^^^^^^^^^^^^^^^^^^^^^^^^^^^^^^^^^^^^^^^^
  File "/usr/local/lib/python3.12/site-packages/django/utils/decorators.py", line 188, in _view_wrapper
    result = _process_exception(request, e)
             ^^^^^^^^^^^^^^^^^^^^^^^^^^^^^^
  File "/usr/local/lib/python3.12/site-packages/django/utils/decorators.py", line 186, in _view_wrapper
    response = view_func(request, *args, **kwargs)
               ^^^^^^^^^^^^^^^^^^^^^^^^^^^^^^^^^^^
  File "/usr/local/lib/python3.12/site-packages/django/views/decorators/cache.py", line 80, in _view_wrapper
    response = view_func(request, *args, **kwargs)
               ^^^^^^^^^^^^^^^^^^^^^^^^^^^^^^^^^^^
  File "/usr/local/lib/python3.12/site-packages/django/contrib/admin/sites.py", line 241, in inner
    return view(request, *args, **kwargs)
           ^^^^^^^^^^^^^^^^^^^^^^^^^^^^^^
  File "/usr/local/lib/python3.12/site-packages/django/utils/decorators.py", line 48, in _wrapper
    return bound_method(*args, **kwargs)
           ^^^^^^^^^^^^^^^^^^^^^^^^^^^^^
  File "/usr/local/lib/python3.12/site-packages/django/utils/decorators.py", line 188, in _view_wrapper
    result = _process_exception(request, e)
             ^^^^^^^^^^^^^^^^^^^^^^^^^^^^^^
  File "/usr/local/lib/python3.12/site-packages/django/utils/decorators.py", line 186, in _view_wrapper
    response = view_func(request, *args, **kwargs)
               ^^^^^^^^^^^^^^^^^^^^^^^^^^^^^^^^^^^
  File "/usr/local/lib/python3.12/site-packages/django/contrib/admin/options.py", line 1999, in changelist_view
    cl = self.get_changelist_instance(request)
         ^^^^^^^^^^^^^^^^^^^^^^^^^^^^^^^^^^^^^
  File "/usr/local/lib/python3.12/site-packages/django/contrib/admin/options.py", line 866, in get_changelist_instance
    return ChangeList(
           ^^^^^^^^^^^
  File "/usr/local/lib/python3.12/site-packages/django/contrib/admin/views/main.py", line 146, in __init__
    self.get_results(request)
  File "/usr/local/lib/python3.12/site-packages/django/contrib/admin/views/main.py", line 313, in get_results
    result_count = paginator.count
                   ^^^^^^^^^^^^^^^
  File "/usr/local/lib/python3.12/site-packages/django/utils/functional.py", line 47, in __get__
    res = instance.__dict__[self.name] = self.func(instance)
                                         ^^^^^^^^^^^^^^^^^^^
  File "/usr/local/lib/python3.12/site-packages/django/core/paginator.py", line 110, in count
    return c()
           ^^^
  File "/usr/local/lib/python3.12/site-packages/django/db/models/query.py", line 620, in count
    return self.query.get_count(using=self.db)
           ^^^^^^^^^^^^^^^^^^^^^^^^^^^^^^^^^^^
  File "/usr/local/lib/python3.12/site-packages/django/db/models/sql/query.py", line 630, in get_count
    return obj.get_aggregation(using, {"__count": Count("*")})["__count"]
           ^^^^^^^^^^^^^^^^^^^^^^^^^^^^^^^^^^^^^^^^^^^^^^^^^^^
  File "/usr/local/lib/python3.12/site-packages/django/db/models/sql/query.py", line 616, in get_aggregation
    result = compiler.execute_sql(SINGLE)
             ^^^^^^^^^^^^^^^^^^^^^^^^^^^^
  File "/usr/local/lib/python3.12/site-packages/django/db/models/sql/compiler.py", line 1574, in execute_sql
    cursor.execute(sql, params)
  File "/usr/local/lib/python3.12/site-packages/django/db/backends/utils.py", line 122, in execute
    return super().execute(sql, params)
           ^^^^^^^^^^^^^^^^^^^^^^^^^^^^
  File "/usr/local/lib/python3.12/site-packages/django/db/backends/utils.py", line 79, in execute
    return self._execute_with_wrappers(
           ^^^^^^^^^^^^^^^^^^^^^^^^^^^^
  File "/usr/local/lib/python3.12/site-packages/django/db/backends/utils.py", line 92, in _execute_with_wrappers
    return executor(sql, params, many, context)
           ^^^^^^^^^^^^^^^^^^^^^^^^^^^^^^^^^^^^
  File "/usr/local/lib/python3.12/site-packages/django/db/backends/utils.py", line 100, in _execute
    with self.db.wrap_database_errors:
         ^^^^^^^^^^^^^^^^^^^^^^^^^^^^
  File "/usr/local/lib/python3.12/site-packages/django/db/utils.py", line 91, in __exit__
    raise dj_exc_value.with_traceback(traceback) from exc_value
  File "/usr/local/lib/python3.12/site-packages/django/db/backends/utils.py", line 105, in _execute
    return self.cursor.execute(sql, params)
           ^^^^^^^^^^^^^^^^^^^^^^^^^^^^^^^^
django.db.utils.ProgrammingError: relation "configurator_item" does not exist
LINE 1: SELECT COUNT(*) AS "__count" FROM "configurator_item"
                                          ^

2025-03-18 13:23:00,654 django.request ERROR    Internal Server Error: /admin/configurator/item/
Traceback (most recent call last):
  File "/usr/local/lib/python3.12/site-packages/django/db/backends/utils.py", line 105, in _execute
    return self.cursor.execute(sql, params)
           ^^^^^^^^^^^^^^^^^^^^^^^^^^^^^^^^
psycopg2.errors.UndefinedTable: relation "configurator_item" does not exist
LINE 1: SELECT COUNT(*) AS "__count" FROM "configurator_item"
                                          ^


The above exception was the direct cause of the following exception:

Traceback (most recent call last):
  File "/usr/local/lib/python3.12/site-packages/django/core/handlers/exception.py", line 55, in inner
    response = get_response(request)
               ^^^^^^^^^^^^^^^^^^^^^
  File "/usr/local/lib/python3.12/site-packages/django/core/handlers/base.py", line 197, in _get_response
    response = wrapped_callback(request, *callback_args, **callback_kwargs)
               ^^^^^^^^^^^^^^^^^^^^^^^^^^^^^^^^^^^^^^^^^^^^^^^^^^^^^^^^^^^^
  File "/usr/local/lib/python3.12/site-packages/django/contrib/admin/options.py", line 718, in wrapper
    return self.admin_site.admin_view(view)(*args, **kwargs)
           ^^^^^^^^^^^^^^^^^^^^^^^^^^^^^^^^^^^^^^^^^^^^^^^^^
  File "/usr/local/lib/python3.12/site-packages/django/utils/decorators.py", line 188, in _view_wrapper
    result = _process_exception(request, e)
             ^^^^^^^^^^^^^^^^^^^^^^^^^^^^^^
  File "/usr/local/lib/python3.12/site-packages/django/utils/decorators.py", line 186, in _view_wrapper
    response = view_func(request, *args, **kwargs)
               ^^^^^^^^^^^^^^^^^^^^^^^^^^^^^^^^^^^
  File "/usr/local/lib/python3.12/site-packages/django/views/decorators/cache.py", line 80, in _view_wrapper
    response = view_func(request, *args, **kwargs)
               ^^^^^^^^^^^^^^^^^^^^^^^^^^^^^^^^^^^
  File "/usr/local/lib/python3.12/site-packages/django/contrib/admin/sites.py", line 241, in inner
    return view(request, *args, **kwargs)
           ^^^^^^^^^^^^^^^^^^^^^^^^^^^^^^
  File "/usr/local/lib/python3.12/site-packages/django/utils/decorators.py", line 48, in _wrapper
    return bound_method(*args, **kwargs)
           ^^^^^^^^^^^^^^^^^^^^^^^^^^^^^
  File "/usr/local/lib/python3.12/site-packages/django/utils/decorators.py", line 188, in _view_wrapper
    result = _process_exception(request, e)
             ^^^^^^^^^^^^^^^^^^^^^^^^^^^^^^
  File "/usr/local/lib/python3.12/site-packages/django/utils/decorators.py", line 186, in _view_wrapper
    response = view_func(request, *args, **kwargs)
               ^^^^^^^^^^^^^^^^^^^^^^^^^^^^^^^^^^^
  File "/usr/local/lib/python3.12/site-packages/django/contrib/admin/options.py", line 1999, in changelist_view
    cl = self.get_changelist_instance(request)
         ^^^^^^^^^^^^^^^^^^^^^^^^^^^^^^^^^^^^^
  File "/usr/local/lib/python3.12/site-packages/django/contrib/admin/options.py", line 866, in get_changelist_instance
    return ChangeList(
           ^^^^^^^^^^^
  File "/usr/local/lib/python3.12/site-packages/django/contrib/admin/views/main.py", line 146, in __init__
    self.get_results(request)
  File "/usr/local/lib/python3.12/site-packages/django/contrib/admin/views/main.py", line 313, in get_results
    result_count = paginator.count
                   ^^^^^^^^^^^^^^^
  File "/usr/local/lib/python3.12/site-packages/django/utils/functional.py", line 47, in __get__
    res = instance.__dict__[self.name] = self.func(instance)
                                         ^^^^^^^^^^^^^^^^^^^
  File "/usr/local/lib/python3.12/site-packages/django/core/paginator.py", line 110, in count
    return c()
           ^^^
  File "/usr/local/lib/python3.12/site-packages/django/db/models/query.py", line 620, in count
    return self.query.get_count(using=self.db)
           ^^^^^^^^^^^^^^^^^^^^^^^^^^^^^^^^^^^
  File "/usr/local/lib/python3.12/site-packages/django/db/models/sql/query.py", line 630, in get_count
    return obj.get_aggregation(using, {"__count": Count("*")})["__count"]
           ^^^^^^^^^^^^^^^^^^^^^^^^^^^^^^^^^^^^^^^^^^^^^^^^^^^
  File "/usr/local/lib/python3.12/site-packages/django/db/models/sql/query.py", line 616, in get_aggregation
    result = compiler.execute_sql(SINGLE)
             ^^^^^^^^^^^^^^^^^^^^^^^^^^^^
  File "/usr/local/lib/python3.12/site-packages/django/db/models/sql/compiler.py", line 1574, in execute_sql
    cursor.execute(sql, params)
  File "/usr/local/lib/python3.12/site-packages/django/db/backends/utils.py", line 122, in execute
    return super().execute(sql, params)
           ^^^^^^^^^^^^^^^^^^^^^^^^^^^^
  File "/usr/local/lib/python3.12/site-packages/django/db/backends/utils.py", line 79, in execute
    return self._execute_with_wrappers(
           ^^^^^^^^^^^^^^^^^^^^^^^^^^^^
  File "/usr/local/lib/python3.12/site-packages/django/db/backends/utils.py", line 92, in _execute_with_wrappers
    return executor(sql, params, many, context)
           ^^^^^^^^^^^^^^^^^^^^^^^^^^^^^^^^^^^^
  File "/usr/local/lib/python3.12/site-packages/django/db/backends/utils.py", line 100, in _execute
    with self.db.wrap_database_errors:
         ^^^^^^^^^^^^^^^^^^^^^^^^^^^^
  File "/usr/local/lib/python3.12/site-packages/django/db/utils.py", line 91, in __exit__
    raise dj_exc_value.with_traceback(traceback) from exc_value
  File "/usr/local/lib/python3.12/site-packages/django/db/backends/utils.py", line 105, in _execute
    return self.cursor.execute(sql, params)
           ^^^^^^^^^^^^^^^^^^^^^^^^^^^^^^^^
django.db.utils.ProgrammingError: relation "configurator_item" does not exist
LINE 1: SELECT COUNT(*) AS "__count" FROM "configurator_item"
                                          ^

2025-03-18 13:23:19,371 django.utils.autoreload INFO     Watching for file changes with StatReloader
2025-03-18 13:25:21,505 django.request ERROR    Internal Server Error: /admin/configurator/item/
Traceback (most recent call last):
  File "/usr/local/lib/python3.12/site-packages/django/db/backends/utils.py", line 105, in _execute
    return self.cursor.execute(sql, params)
           ^^^^^^^^^^^^^^^^^^^^^^^^^^^^^^^^
psycopg2.errors.UndefinedTable: relation "configurator_item" does not exist
LINE 1: SELECT COUNT(*) AS "__count" FROM "configurator_item"
                                          ^


The above exception was the direct cause of the following exception:

Traceback (most recent call last):
  File "/usr/local/lib/python3.12/site-packages/django/core/handlers/exception.py", line 55, in inner
    response = get_response(request)
               ^^^^^^^^^^^^^^^^^^^^^
  File "/usr/local/lib/python3.12/site-packages/django/core/handlers/base.py", line 197, in _get_response
    response = wrapped_callback(request, *callback_args, **callback_kwargs)
               ^^^^^^^^^^^^^^^^^^^^^^^^^^^^^^^^^^^^^^^^^^^^^^^^^^^^^^^^^^^^
  File "/usr/local/lib/python3.12/site-packages/django/contrib/admin/options.py", line 718, in wrapper
    return self.admin_site.admin_view(view)(*args, **kwargs)
           ^^^^^^^^^^^^^^^^^^^^^^^^^^^^^^^^^^^^^^^^^^^^^^^^^
  File "/usr/local/lib/python3.12/site-packages/django/utils/decorators.py", line 188, in _view_wrapper
    result = _process_exception(request, e)
             ^^^^^^^^^^^^^^^^^^^^^^^^^^^^^^
  File "/usr/local/lib/python3.12/site-packages/django/utils/decorators.py", line 186, in _view_wrapper
    response = view_func(request, *args, **kwargs)
               ^^^^^^^^^^^^^^^^^^^^^^^^^^^^^^^^^^^
  File "/usr/local/lib/python3.12/site-packages/django/views/decorators/cache.py", line 80, in _view_wrapper
    response = view_func(request, *args, **kwargs)
               ^^^^^^^^^^^^^^^^^^^^^^^^^^^^^^^^^^^
  File "/usr/local/lib/python3.12/site-packages/django/contrib/admin/sites.py", line 241, in inner
    return view(request, *args, **kwargs)
           ^^^^^^^^^^^^^^^^^^^^^^^^^^^^^^
  File "/usr/local/lib/python3.12/site-packages/django/utils/decorators.py", line 48, in _wrapper
    return bound_method(*args, **kwargs)
           ^^^^^^^^^^^^^^^^^^^^^^^^^^^^^
  File "/usr/local/lib/python3.12/site-packages/django/utils/decorators.py", line 188, in _view_wrapper
    result = _process_exception(request, e)
             ^^^^^^^^^^^^^^^^^^^^^^^^^^^^^^
  File "/usr/local/lib/python3.12/site-packages/django/utils/decorators.py", line 186, in _view_wrapper
    response = view_func(request, *args, **kwargs)
               ^^^^^^^^^^^^^^^^^^^^^^^^^^^^^^^^^^^
  File "/usr/local/lib/python3.12/site-packages/django/contrib/admin/options.py", line 1999, in changelist_view
    cl = self.get_changelist_instance(request)
         ^^^^^^^^^^^^^^^^^^^^^^^^^^^^^^^^^^^^^
  File "/usr/local/lib/python3.12/site-packages/django/contrib/admin/options.py", line 866, in get_changelist_instance
    return ChangeList(
           ^^^^^^^^^^^
  File "/usr/local/lib/python3.12/site-packages/django/contrib/admin/views/main.py", line 146, in __init__
    self.get_results(request)
  File "/usr/local/lib/python3.12/site-packages/django/contrib/admin/views/main.py", line 313, in get_results
    result_count = paginator.count
                   ^^^^^^^^^^^^^^^
  File "/usr/local/lib/python3.12/site-packages/django/utils/functional.py", line 47, in __get__
    res = instance.__dict__[self.name] = self.func(instance)
                                         ^^^^^^^^^^^^^^^^^^^
  File "/usr/local/lib/python3.12/site-packages/django/core/paginator.py", line 110, in count
    return c()
           ^^^
  File "/usr/local/lib/python3.12/site-packages/django/db/models/query.py", line 620, in count
    return self.query.get_count(using=self.db)
           ^^^^^^^^^^^^^^^^^^^^^^^^^^^^^^^^^^^
  File "/usr/local/lib/python3.12/site-packages/django/db/models/sql/query.py", line 630, in get_count
    return obj.get_aggregation(using, {"__count": Count("*")})["__count"]
           ^^^^^^^^^^^^^^^^^^^^^^^^^^^^^^^^^^^^^^^^^^^^^^^^^^^
  File "/usr/local/lib/python3.12/site-packages/django/db/models/sql/query.py", line 616, in get_aggregation
    result = compiler.execute_sql(SINGLE)
             ^^^^^^^^^^^^^^^^^^^^^^^^^^^^
  File "/usr/local/lib/python3.12/site-packages/django/db/models/sql/compiler.py", line 1574, in execute_sql
    cursor.execute(sql, params)
  File "/usr/local/lib/python3.12/site-packages/django/db/backends/utils.py", line 122, in execute
    return super().execute(sql, params)
           ^^^^^^^^^^^^^^^^^^^^^^^^^^^^
  File "/usr/local/lib/python3.12/site-packages/django/db/backends/utils.py", line 79, in execute
    return self._execute_with_wrappers(
           ^^^^^^^^^^^^^^^^^^^^^^^^^^^^
  File "/usr/local/lib/python3.12/site-packages/django/db/backends/utils.py", line 92, in _execute_with_wrappers
    return executor(sql, params, many, context)
           ^^^^^^^^^^^^^^^^^^^^^^^^^^^^^^^^^^^^
  File "/usr/local/lib/python3.12/site-packages/django/db/backends/utils.py", line 100, in _execute
    with self.db.wrap_database_errors:
         ^^^^^^^^^^^^^^^^^^^^^^^^^^^^
  File "/usr/local/lib/python3.12/site-packages/django/db/utils.py", line 91, in __exit__
    raise dj_exc_value.with_traceback(traceback) from exc_value
  File "/usr/local/lib/python3.12/site-packages/django/db/backends/utils.py", line 105, in _execute
    return self.cursor.execute(sql, params)
           ^^^^^^^^^^^^^^^^^^^^^^^^^^^^^^^^
django.db.utils.ProgrammingError: relation "configurator_item" does not exist
LINE 1: SELECT COUNT(*) AS "__count" FROM "configurator_item"
                                          ^

2025-03-18 13:26:27,242 django.utils.autoreload INFO     Watching for file changes with StatReloader
2025-03-18 13:28:05,848 django.utils.autoreload INFO     Watching for file changes with StatReloader
2025-03-18 13:43:25,837 django.utils.autoreload INFO     /app/configurator/models.py changed, reloading.
2025-03-18 13:43:26,046 django.utils.autoreload INFO     Watching for file changes with StatReloader
2025-03-18 13:45:40,680 django.utils.autoreload INFO     /app/configurator/models.py changed, reloading.
2025-03-18 13:45:40,880 django.utils.autoreload INFO     Watching for file changes with StatReloader
2025-03-18 13:46:05,068 django.utils.autoreload INFO     /app/configurator/migrations/0001_initial.py changed, reloading.
2025-03-18 13:46:05,276 django.utils.autoreload INFO     Watching for file changes with StatReloader
2025-03-18 13:47:56,747 django.utils.autoreload INFO     Watching for file changes with StatReloader
2025-03-18 13:53:44,550 django.utils.autoreload INFO     Watching for file changes with StatReloader
2025-03-18 13:54:31,831 django.utils.autoreload INFO     /app/configurator/models.py changed, reloading.
2025-03-18 13:54:32,028 django.utils.autoreload INFO     Watching for file changes with StatReloader
2025-03-18 14:06:39,044 django.utils.autoreload INFO     /app/cpq/urls.py changed, reloading.
2025-03-18 14:06:39,277 django.utils.autoreload INFO     Watching for file changes with StatReloader
2025-03-18 14:07:20,227 django.utils.autoreload INFO     Watching for file changes with StatReloader
2025-03-18 14:18:14,591 django.utils.autoreload INFO     /app/configurator/views.py changed, reloading.
2025-03-18 14:18:14,784 django.utils.autoreload INFO     Watching for file changes with StatReloader
2025-03-18 14:18:22,205 django.request ERROR    Internal Server Error: /
Traceback (most recent call last):
  File "/usr/local/lib/python3.12/site-packages/django/db/models/fields/__init__.py", line 2123, in get_prep_value
    return int(value)
           ^^^^^^^^^^
ValueError: invalid literal for int() with base 10: ''

The above exception was the direct cause of the following exception:

Traceback (most recent call last):
  File "/usr/local/lib/python3.12/site-packages/django/core/handlers/exception.py", line 55, in inner
    response = get_response(request)
               ^^^^^^^^^^^^^^^^^^^^^
  File "/usr/local/lib/python3.12/site-packages/django/core/handlers/base.py", line 197, in _get_response
    response = wrapped_callback(request, *callback_args, **callback_kwargs)
               ^^^^^^^^^^^^^^^^^^^^^^^^^^^^^^^^^^^^^^^^^^^^^^^^^^^^^^^^^^^^
  File "/app/configurator/views.py", line 11, in index
    for item in Item.objects.filter(product=""):
                ^^^^^^^^^^^^^^^^^^^^^^^^^^^^^^^
  File "/usr/local/lib/python3.12/site-packages/django/db/models/manager.py", line 87, in manager_method
    return getattr(self.get_queryset(), name)(*args, **kwargs)
           ^^^^^^^^^^^^^^^^^^^^^^^^^^^^^^^^^^^^^^^^^^^^^^^^^^^
  File "/usr/local/lib/python3.12/site-packages/django/db/models/query.py", line 1476, in filter
    return self._filter_or_exclude(False, args, kwargs)
           ^^^^^^^^^^^^^^^^^^^^^^^^^^^^^^^^^^^^^^^^^^^^
  File "/usr/local/lib/python3.12/site-packages/django/db/models/query.py", line 1494, in _filter_or_exclude
    clone._filter_or_exclude_inplace(negate, args, kwargs)
  File "/usr/local/lib/python3.12/site-packages/django/db/models/query.py", line 1501, in _filter_or_exclude_inplace
    self._query.add_q(Q(*args, **kwargs))
  File "/usr/local/lib/python3.12/site-packages/django/db/models/sql/query.py", line 1609, in add_q
    clause, _ = self._add_q(q_object, self.used_aliases)
                ^^^^^^^^^^^^^^^^^^^^^^^^^^^^^^^^^^^^^^^^
  File "/usr/local/lib/python3.12/site-packages/django/db/models/sql/query.py", line 1641, in _add_q
    child_clause, needed_inner = self.build_filter(
                                 ^^^^^^^^^^^^^^^^^^
  File "/usr/local/lib/python3.12/site-packages/django/db/models/sql/query.py", line 1555, in build_filter
    condition = self.build_lookup(lookups, col, value)
                ^^^^^^^^^^^^^^^^^^^^^^^^^^^^^^^^^^^^^^
  File "/usr/local/lib/python3.12/site-packages/django/db/models/sql/query.py", line 1385, in build_lookup
    lookup = lookup_class(lhs, rhs)
             ^^^^^^^^^^^^^^^^^^^^^^
  File "/usr/local/lib/python3.12/site-packages/django/db/models/lookups.py", line 30, in __init__
    self.rhs = self.get_prep_lookup()
               ^^^^^^^^^^^^^^^^^^^^^^
  File "/usr/local/lib/python3.12/site-packages/django/db/models/fields/related_lookups.py", line 156, in get_prep_lookup
    self.rhs = target_field.get_prep_value(self.rhs)
               ^^^^^^^^^^^^^^^^^^^^^^^^^^^^^^^^^^^^^
  File "/usr/local/lib/python3.12/site-packages/django/db/models/fields/__init__.py", line 2125, in get_prep_value
    raise e.__class__(
ValueError: Field 'id' expected a number but got ''.
2025-03-18 14:18:36,060 django.utils.autoreload INFO     /app/configurator/views.py changed, reloading.
2025-03-18 14:18:36,264 django.utils.autoreload INFO     Watching for file changes with StatReloader
2025-03-18 14:19:54,715 django.utils.autoreload INFO     /app/configurator/views.py changed, reloading.
2025-03-18 14:19:54,905 django.utils.autoreload INFO     Watching for file changes with StatReloader
2025-03-18 14:19:57,583 root         INFO     Полочка
2025-03-18 14:20:00,452 root         INFO     Полочка
2025-03-18 14:20:01,372 root         INFO     Полочка
2025-03-18 14:20:01,886 root         INFO     Полочка
2025-03-18 14:20:02,077 root         INFO     Полочка
2025-03-18 14:20:02,270 root         INFO     Полочка
2025-03-18 14:20:02,464 root         INFO     Полочка
2025-03-18 14:20:02,688 root         INFO     Полочка
2025-03-18 14:21:02,286 django.utils.autoreload INFO     /app/configurator/services/graph.py changed, reloading.
2025-03-18 14:21:02,488 django.utils.autoreload INFO     Watching for file changes with StatReloader
2025-03-18 14:21:05,051 root         INFO     ---Полочка added
2025-03-18 14:21:05,052 root         INFO     ---С резинкой added
2025-03-18 14:21:05,053 root         INFO     ---Со шнурком added
2025-03-18 14:21:05,053 root         INFO     ---Кулиса added
2025-03-18 14:21:05,054 root         INFO     ---Кулиса-С резинкой edge added
2025-03-18 14:21:05,054 root         INFO     ---Кулиса-Со шнурком edge added
2025-03-18 14:21:05,054 root         INFO     Полочка
2025-03-18 14:21:09,952 root         INFO     ---Полочка added
2025-03-18 14:21:09,953 root         INFO     ---С резинкой added
2025-03-18 14:21:09,954 root         INFO     ---Со шнурком added
2025-03-18 14:21:09,954 root         INFO     ---Кулиса added
2025-03-18 14:21:09,955 root         INFO     ---Кулиса-С резинкой edge added
2025-03-18 14:21:09,955 root         INFO     ---Кулиса-Со шнурком edge added
2025-03-18 14:21:09,955 root         INFO     Полочка
2025-03-18 14:21:57,864 django.utils.autoreload INFO     /app/configurator/services/graph.py changed, reloading.
2025-03-18 14:21:58,072 django.utils.autoreload INFO     Watching for file changes with StatReloader
2025-03-18 14:21:59,899 root         INFO     ---Полочка added
2025-03-18 14:21:59,900 root         INFO     ---С резинкой added
2025-03-18 14:21:59,900 root         INFO     ---Со шнурком added
2025-03-18 14:21:59,901 root         INFO     ---Кулиса added
2025-03-18 14:21:59,902 root         INFO     ---Кулиса-С резинкой edge added
2025-03-18 14:21:59,902 root         INFO     ---Кулиса-Со шнурком edge added
2025-03-18 14:21:59,902 root         INFO     {'Полочка': [], 'С резинкой': [], 'Со шнурком': [], 'Кулиса': ['С резинкой', 'Со шнурком']}
2025-03-18 14:21:59,902 root         INFO     Полочка
2025-03-18 14:31:38,620 django.utils.autoreload INFO     /app/configurator/models.py changed, reloading.
2025-03-18 14:31:38,833 django.utils.autoreload INFO     Watching for file changes with StatReloader
2025-03-18 14:32:30,117 django.utils.autoreload INFO     /app/configurator/models.py changed, reloading.
2025-03-18 14:32:30,293 django.utils.autoreload INFO     Watching for file changes with StatReloader
2025-03-18 14:32:38,446 django.utils.autoreload INFO     /app/configurator/models.py changed, reloading.
2025-03-18 14:32:38,651 django.utils.autoreload INFO     Watching for file changes with StatReloader
2025-03-18 14:32:46,782 django.utils.autoreload INFO     /app/configurator/models.py changed, reloading.
2025-03-18 14:32:47,031 django.utils.autoreload INFO     Watching for file changes with StatReloader
2025-03-18 14:34:35,559 django.utils.autoreload INFO     /app/configurator/models.py changed, reloading.
2025-03-18 14:34:35,754 django.utils.autoreload INFO     Watching for file changes with StatReloader
2025-03-18 14:54:16,364 django.utils.autoreload INFO     /app/configurator/models.py changed, reloading.
2025-03-18 14:54:16,634 django.utils.autoreload INFO     Watching for file changes with StatReloader
2025-03-18 14:56:34,243 django.utils.autoreload INFO     /app/configurator/models.py changed, reloading.
2025-03-18 14:56:34,456 django.utils.autoreload INFO     Watching for file changes with StatReloader
2025-03-18 15:05:01,431 django.utils.autoreload INFO     /app/configurator/models.py changed, reloading.
2025-03-18 15:05:01,659 django.utils.autoreload INFO     Watching for file changes with StatReloader
2025-03-18 15:15:23,008 django.utils.autoreload INFO     /app/configurator/models.py changed, reloading.
2025-03-18 15:15:23,213 django.utils.autoreload INFO     Watching for file changes with StatReloader
2025-03-18 15:19:38,124 django.utils.autoreload INFO     /app/configurator/models.py changed, reloading.
2025-03-18 15:19:38,323 django.utils.autoreload INFO     Watching for file changes with StatReloader
2025-03-18 15:32:02,689 django.utils.autoreload INFO     /app/configurator/models.py changed, reloading.
2025-03-18 15:32:02,894 django.utils.autoreload INFO     Watching for file changes with StatReloader
2025-03-18 15:33:05,189 django.utils.autoreload INFO     /app/configurator/models.py changed, reloading.
2025-03-18 15:33:05,391 django.utils.autoreload INFO     Watching for file changes with StatReloader
2025-03-18 15:36:04,153 django.utils.autoreload INFO     /app/configurator/models.py changed, reloading.
2025-03-18 15:36:04,353 django.utils.autoreload INFO     Watching for file changes with StatReloader
